Workbook
Name AllTeams: Lists!$A$2:$A$49
Name GroupA_Teams: Lists!$B$2:$B$5
Name GroupB_Teams: Lists!$C$2:$C$5
Name GroupC_Teams: Lists!$D$2:$D$5
Name GroupD_Teams: Lists!$E$2:$E$5
Name GroupE_Teams: Lists!$F$2:$F$5
Name GroupF_Teams: Lists!$G$2:$G$5
Name GroupG_Teams: Lists!$H$2:$H$5
Name GroupH_Teams: Lists!$I$2:$I$5
Name GroupI_Teams: Lists!$J$2:$J$5
Name GroupJ_Teams: Lists!$K$2:$K$5
Name GroupK_Teams: Lists!$L$2:$L$5
Name GroupL_Teams: Lists!$M$2:$M$5
Name KO_Final: Lists!$AS$2:$AS$3
Name KO_QF_1: Lists!$AM$2:$AM$3
Name KO_QF_2: Lists!$AN$2:$AN$3
Name KO_QF_3: Lists!$AO$2:$AO$3
Name KO_QF_4: Lists!$AP$2:$AP$3
Name KO_R16_1: Lists!$AE$2:$AE$3
Name KO_R16_2: Lists!$AF$2:$AF$3
Name KO_R16_3: Lists!$AG$2:$AG$3
Name KO_R16_4: Lists!$AH$2:$AH$3
Name KO_R16_5: Lists!$AI$2:$AI$3
Name KO_R16_6: Lists!$AJ$2:$AJ$3
Name KO_R16_7: Lists!$AK$2:$AK$3
Name KO_R16_8: Lists!$AL$2:$AL$3
Name KO_R32_M73: Lists!$O$2:$O$3
Name KO_R32_M74: Lists!$P$2:$P$3
Name KO_R32_M75: Lists!$Q$2:$Q$3
Name KO_R32_M76: Lists!$R$2:$R$3
Name KO_R32_M77: Lists!$S$2:$S$3
Name KO_R32_M78: Lists!$T$2:$T$3
Name KO_R32_M79: Lists!$U$2:$U$3
Name KO_R32_M80: Lists!$V$2:$V$3
Name KO_R32_M81: Lists!$W$2:$W$3
Name KO_R32_M82: Lists!$X$2:$X$3
Name KO_R32_M83: Lists!$Y$2:$Y$3
Name KO_R32_M84: Lists!$Z$2:$Z$3
Name KO_R32_M85: Lists!$AA$2:$AA$3
Name KO_R32_M86: Lists!$AB$2:$AB$3
Name KO_R32_M87: Lists!$AC$2:$AC$3
Name KO_R32_M88: Lists!$AD$2:$AD$3
Name KO_SF_1: Lists!$AQ$2:$AQ$3
Name KO_SF_2: Lists!$AR$2:$AR$3
Name KO_Third: Lists!$AT$2:$AT$3

Sheet Instructions & Rules
A1: FIFA World Cup 2026 Prediction Game Workbook
J3: Scoring item | K3: Points | M3: Team lookup for dropdowns | O3: Yes/No list
A4: Ready-to-use workbook structure for a private friends' pool. Update the official team names first, then collect predictions round by round. | B4: Ready-to-use workbook structure for a private friends' pool. Update the official team names first, then collect predictions round by round. | C4: Ready-to-use workbook structure for a private friends' pool. Update the official team names first, then collect predictions round by round. | D4: Ready-to-use workbook structure for a private friends' pool. Update the official team names first, then collect predictions round by round. | E4: Ready-to-use workbook structure for a private friends' pool. Update the official team names first, then collect predictions round by round. | F4: Ready-to-use workbook structure for a private friends' pool. Update the official team names first, then collect predictions round by round. | G4: Ready-to-use workbook structure for a private friends' pool. Update the official team names first, then collect predictions round by round. | H4: Ready-to-use workbook structure for a private friends' pool. Update the official team names first, then collect predictions round by round. | J4: Group exact 1st place | K4: 4 | M4: ='Official Results'!C6 -> Mexico | O4: Yes
J5: Group exact 2nd place | K5: 4 | M5: ='Official Results'!C7 -> South Africa | O5: No
A6: Game overview | B6: Game overview | C6: Game overview | D6: Game overview | E6: Game overview | F6: Game overview | G6: Game overview | H6: Game overview | J6: Group wrong-order top 2 | K6: 1 | M6: ='Official Results'!C8 -> Korea Republic
A7: 1 | B7: Official format | C7: 48 teams | D7: 12 groups of 4 | E7: Top 2 in each group + 8 best third-placed teams advance to the Round of 32. | J7: Group qualified 3rd-place team | K7: 2 | M7: ='Official Results'!C9 -> Czechia
A8: 2 | B8: Workflow | C8: Group stage first | D8: Then knockout rounds | E8: Players enter predictions round by round; the workbook scores automatically after results are filled in. | J8: Group exact top-2 bonus | K8: 2 | M8: ='Official Results'!J6 -> Switzerland
A9: 3 | B9: Scoring | C9: Group stage + knockout | D9: Leaderboards + dashboard | E9: Edit the point values in the scoring table at right if you want to tweak the game. | J9: Group full top-3 bonus | K9: 3 | M9: ='Official Results'!J7 -> Canada
J10: Round of 32 correct winner | K10: 2 | M10: ='Official Results'!J8 -> Bosnia and Herzegovina
J11: Round of 16 correct winner | K11: 4 | M11: ='Official Results'!J9 -> Qatar
A12: References and notes | B12: References and notes | C12: References and notes | D12: References and notes | E12: References and notes | F12: References and notes | G12: References and notes | H12: References and notes | J12: Quarter-final correct winner | K12: 8 | M12: ='Official Results'!Q6 -> Brazil
A13: FIFA official format | B13: 48 teams, 12 groups of 4, 8 best third-placed teams | C13: Use the same structure in the workbook. | J13: Semi-final correct winner | K13: 16 | M13: ='Official Results'!Q7 -> Morocco
A14: User reference | B14: Wikipedia page shared in the prompt | C14: Kept as a note for convenience. | J14: Final correct runner-up | K14: 16 | M14: ='Official Results'!Q8 -> Scotland
J15: Champion bonus | K15: 20 | M15: ='Official Results'!Q9 -> Haiti
A16: How to use | B16: How to use | C16: How to use | D16: How to use | E16: How to use | F16: How to use | G16: How to use | H16: How to use | J16: Third-place match winner | K16: 8 | M16: ='Official Results'!X6 -> United States
A17: 1 | B17: Update official team names | C17: Replace the placeholder teams in Official Results first. | M17: ='Official Results'!X7 -> Australia
A18: 2 | B18: Enter player names | C18: Use the Players sheet for up to 20 participants. | M18: ='Official Results'!X8 -> Paraguay
A19: 3 | B19: Collect predictions | C19: Fill each round sheet after the tournament reaches that stage. | M19: ='Official Results'!X9 -> Türkiye
A20: 4 | B20: Add actual results | C20: Enter standings and winners on Official Results; scores update automatically. | M20: ='Official Results'!C13 -> Germany
M21: ='Official Results'!C14 -> Côte d'Ivoire
M22: ='Official Results'!C15 -> Ecuador
M23: ='Official Results'!C16 -> Curaçao
M24: ='Official Results'!J13 -> Netherlands
M25: ='Official Results'!J14 -> Japan
M26: ='Official Results'!J15 -> Sweden
M27: ='Official Results'!J16 -> Tunisia
M28: ='Official Results'!Q13 -> Belgium
M29: ='Official Results'!Q14 -> Egypt
M30: ='Official Results'!Q15 -> IR Iran
M31: ='Official Results'!Q16 -> New Zealand
M32: ='Official Results'!X13 -> Spain
M33: ='Official Results'!X14 -> Cabo Verde
M34: ='Official Results'!X15 -> Uruguay
M35: ='Official Results'!X16 -> Saudi Arabia
M36: ='Official Results'!C20 -> France
M37: ='Official Results'!C21 -> Norway
M38: ='Official Results'!C22 -> Senegal
M39: ='Official Results'!C23 -> Iraq
M40: ='Official Results'!J20 -> Argentina
M41: ='Official Results'!J21 -> Austria
...

Sheet Players
A1: Players and entry order
A4: Edit player names here. The workbook supports up to 20 players. | B4: Edit player names here. The workbook supports up to 20 players. | C4: Edit player names here. The workbook supports up to 20 players. | D4: Edit player names here. The workbook supports up to 20 players. | E4: Edit player names here. The workbook supports up to 20 players.
A5: Entry Order | B5: Player Name | C5: Starting Points | D5: Active | E5: Notes
A6: 1 | B6: Febby Yudhi Pratama | C6: 0 | D6: Yes
A7: 2 | B7: Fathan Mauludin | C7: 0 | D7: Yes
A8: 3 | B8: M Fakhri Auladana | C8: 0 | D8: Yes
A9: 4 | B9: Muhammad Naufal Aiman | C9: 0 | D9: Yes
A10: 5 | B10: Ahade | C10: 0 | D10: Yes
A11: 6 | B11: Aldy | C11: 0 | D11: Yes
A12: 7 | B12: Affaninho | C12: 0 | D12: Yes
A13: 8 | B13: Aji | C13: 0 | D13: Yes
A14: 9 | B14: Dausman | C14: 0 | D14: Yes
A15: 10 | B15: Wawa | C15: 0 | D15: Yes
A16: 11 | B16: Player 11 | C16: 0 | D16: Yes
A17: 12 | B17: Player 12 | C17: 0 | D17: Yes
... A25: 20 | B25: Player 20 | C25: 0 | D25: No

Sheet Official Results
A1: Official Results (admin input)
B3: Group A | I3: Group B | P3: Group C | W3: Group D
A4: Enter match scores in the fixtures table below. Only the yellow score cells are editable; standings update automatically. | W4: Group D
B5: Pos | C5: Team | D5: Pts | E5: GD | F5: GF | G5: Qualified? | I5: Pos | J5: Team | K5: Pts | L5: GD | M5: GF | N5: Qualified? | P5: Pos | Q5: Team | R5: Pts | S5: GD | T5: GF | U5: Qualified? | W5: Pos | X5: Team | Y5: Pts | Z5: GD | AA5: GF | AB5: Qualified?
A6: Group stage standings | B6: 1 | C6: =INDEX($B$135:$B$138,MATCH($B6,$L$135:$L$138,0)) -> Mexico | D6: =INDEX($J$135:$J$138,MATCH($B6,$L$135:$L$138,0)) -> 9 | E6: =INDEX($I$135:$I$138,MATCH($B6,$L$135:$L$138,0)) -> 6 | F6: =INDEX($G$135:$G$138,MATCH($B6,$L$135:$L$138,0)) -> 6 | G6: =INDEX($N$135:$N$138,MATCH($B6,$L$135:$L$138,0)) -> Yes | H6: Group stage standings | I6: 1 | J6: =INDEX($B$139:$B$142,MATCH($I6,$L$139:$L$142,0)) -> Switzerland | K6: =INDEX($J$139:$J$142,MATCH($I6,$L$139:$L$142,0)) -> 7 | L6: =INDEX($I$139:$I$142,MATCH($I6,$L$139:$L$142,0)) -> 4 | M6: =INDEX($G$139:$G$142,MATCH($I6,$L$139:$L$142,0)) -> 7 | N6: =INDEX($N$139:$N$142,MATCH($I6,$L$139:$L$142,0)) -> Yes | O6: Group stage standings | P6: 1 | Q6: =INDEX($B$143:$B$146,MATCH($P6,$L$143:$L$146,0)) -> Brazil | R6: =INDEX($J$143:$J$146,MATCH($P6,$L$143:$L$146,0)) -> 7 | S6: =INDEX($I$143:$I$146,MATCH($P6,$L$143:$L$146,0)) -> 6 | T6: =INDEX($G$143:$G$146,MATCH($P6,$L$143:$L$146,0)) -> 7 | U6: =INDEX($N$143:$N$146,MATCH($P6,$L$143:$L$146,0)) -> Yes | W6: 1 | X6: =INDEX($B$147:$B$150,MATCH($W6,$L$147:$L$150,0)) -> United States | Y6: =INDEX($J$147:$J$150,MATCH($W6,$L$147:$L$150,0)) -> 6 | Z6: =INDEX($I$147:$I$150,MATCH($W6,$L$147:$L$150,0)) -> 4 | AA6: =INDEX($G$147:$G$150,MATCH($W6,$L$147:$L$150,0)) -> 8 | AB6: =INDEX($N$147:$N$150,MATCH($W6,$L$147:$L$150,0)) -> Yes
B7: 2 | C7: =INDEX($B$135:$B$138,MATCH($B7,$L$135:$L$138,0)) -> South Africa | D7: =INDEX($J$135:$J$138,MATCH($B7,$L$135:$L$138,0)) -> 4 | E7: =INDEX($I$135:$I$138,MATCH($B7,$L$135:$L$138,0)) -> -1 | F7: =INDEX($G$135:$G$138,MATCH($B7,$L$135:$L$138,0)) -> 2 | G7: =INDEX($N$135:$N$138,MATCH($B7,$L$135:$L$138,0)) -> Yes | I7: 2 | J7: =INDEX($B$139:$B$142,MATCH($I7,$L$139:$L$142,0)) -> Canada | K7: =INDEX($J$139:$J$142,MATCH($I7,$L$139:$L$142,0)) -> 4 | L7: =INDEX($I$139:$I$142,MATCH($I7,$L$139:$L$142,0)) -> 5 | M7: =INDEX($G$139:$G$142,MATCH($I7,$L$139:$L$142,0)) -> 8 | N7: =INDEX($N$139:$N$142,MATCH($I7,$L$139:$L$142,0)) -> Yes | P7: 2 | Q7: =INDEX($B$143:$B$146,MATCH($P7,$L$143:$L$146,0)) -> Morocco | R7: =INDEX($J$143:$J$146,MATCH($P7,$L$143:$L$146,0)) -> 7 | S7: =INDEX($I$143:$I$146,MATCH($P7,$L$143:$L$146,0)) -> 3 | T7: =INDEX($G$143:$G$146,MATCH($P7,$L$143:$L$146,0)) -> 6 | U7: =INDEX($N$143:$N$146,MATCH($P7,$L$143:$L$146,0)) -> Yes | W7: 2 | X7: =INDEX($B$147:$B$150,MATCH($W7,$L$147:$L$150,0)) -> Australia | Y7: =INDEX($J$147:$J$150,MATCH($W7,$L$147:$L$150,0)) -> 4 | Z7: =INDEX($I$147:$I$150,MATCH($W7,$L$147:$L$150,0)) -> 0 | AA7: =INDEX($G$147:$G$150,MATCH($W7,$L$147:$L$150,0)) -> 2 | AB7: =INDEX($N$147:$N$150,MATCH($W7,$L$147:$L$150,0)) -> Yes
B8: 3 | C8: =INDEX($B$135:$B$138,MATCH($B8,$L$135:$L$138,0)) -> Korea Republic | D8: =INDEX($J$135:$J$138,MATCH($B8,$L$135:$L$138,0)) -> 3 | E8: =INDEX($I$135:$I$138,MATCH($B8,$L$135:$L$138,0)) -> -1 | F8: =INDEX($G$135:$G$138,MATCH($B8,$L$135:$L$138,0)) -> 2 | G8: =INDEX($N$135:$N$138,MATCH($B8,$L$135:$L$138,0)) -> No | I8: 3 | J8: =INDEX($B$139:$B$142,MATCH($I8,$L$139:$L$142,0)) -> Bosnia and Herzegovina | K8: =INDEX($J$139:$J$142,MATCH($I8,$L$139:$L$142,0)) -> 4 | L8: =INDEX($I$139:$I$142,MATCH($I8,$L$139:$L$142,0)) -> -1 | M8: =INDEX($G$139:$G$142,MATCH($I8,$L$139:$L$142,0)) -> 5 | N8: =INDEX($N$139:$N$142,MATCH($I8,$L$139:$L$142,0)) -> Yes | P8: 3 | Q8: =INDEX($B$143:$B$146,MATCH($P8,$L$143:$L$146,0)) -> Scotland | R8: =INDEX($J$143:$J$146,MATCH($P8,$L$143:$L$146,0)) -> 3 | S8: =INDEX($I$143:$I$146,MATCH($P8,$L$143:$L$146,0)) -> -3 | T8: =INDEX($G$143:$G$146,MATCH($P8,$L$143:$L$146,0)) -> 1 | U8: =INDEX($N$143:$N$146,MATCH($P8,$L$143:$L$146,0)) -> No | W8: 3 | X8: =INDEX($B$147:$B$150,MATCH($W8,$L$147:$L$150,0)) -> Paraguay | Y8: =INDEX($J$147:$J$150,MATCH($W8,$L$147:$L$150,0)) -> 4 | Z8: =INDEX($I$147:$I$150,MATCH($W8,$L$147:$L$150,0)) -> -2 | AA8: =INDEX($G$147:$G$150,MATCH($W8,$L$147:$L$150,0)) -> 2 | AB8: =INDEX($N$147:$N$150,MATCH($W8,$L$147:$L$150,0)) -> Yes
B9: 4 | C9: =INDEX($B$135:$B$138,MATCH($B9,$L$135:$L$138,0)) -> Czechia | D9: =INDEX($J$135:$J$138,MATCH($B9,$L$135:$L$138,0)) -> 1 | E9: =INDEX($I$135:$I$138,MATCH($B9,$L$135:$L$138,0)) -> -4 | F9: =INDEX($G$135:$G$138,MATCH($B9,$L$135:$L$138,0)) -> 2 | G9: =INDEX($N$135:$N$138,MATCH($B9,$L$135:$L$138,0)) -> No | I9: 4 | J9: =INDEX($B$139:$B$142,MATCH($I9,$L$139:$L$142,0)) -> Qatar | K9: =INDEX($J$139:$J$142,MATCH($I9,$L$139:$L$142,0)) -> 1 | L9: =INDEX($I$139:$I$142,MATCH($I9,$L$139:$L$142,0)) -> -8 | M9: =INDEX($G$139:$G$142,MATCH($I9,$L$139:$L$142,0)) -> 2 | N9: =INDEX($N$139:$N$142,MATCH($I9,$L$139:$L$142,0)) -> No | P9: 4 | Q9: =INDEX($B$143:$B$146,MATCH($P9,$L$143:$L$146,0)) -> Haiti | R9: =INDEX($J$143:$J$146,MATCH($P9,$L$143:$L$146,0)) -> 0 | S9: =INDEX($I$143:$I$146,MATCH($P9,$L$143:$L$146,0)) -> -6 | T9: =INDEX($G$143:$G$146,MATCH($P9,$L$143:$L$146,0)) -> 2 | U9: =INDEX($N$143:$N$146,MATCH($P9,$L$143:$L$146,0)) -> No | W9: 4 | X9: =INDEX($B$147:$B$150,MATCH($W9,$L$147:$L$150,0)) -> Türkiye | Y9: =INDEX($J$147:$J$150,MATCH($W9,$L$147:$L$150,0)) -> 3 | Z9: =INDEX($I$147:$I$150,MATCH($W9,$L$147:$L$150,0)) -> -2 | AA9: =INDEX($G$147:$G$150,MATCH($W9,$L$147:$L$150,0)) -> 3 | AB9: =INDEX($N$147:$N$150,MATCH($W9,$L$147:$L$150,0)) -> No
B11: Group E | I11: Group F | P11: Group G | W11: Group H
B12: Pos | C12: Team | D12: Pts | E12: GD | F12: GF | G12: Qualified? | I12: Pos | J12: Team | K12: Pts | L12: GD | M12: GF | N12: Qualified? | P12: Pos | Q12: Team | R12: Pts | S12: GD | T12: GF | U12: Qualified? | W12: Pos | X12: Team | Y12: Pts | Z12: GD | AA12: GF | AB12: Qualified?
B13: 1 | C13: =INDEX($B$151:$B$154,MATCH($B13,$L$151:$L$154,0)) -> Germany | D13: =INDEX($J$151:$J$154,MATCH($B13,$L$151:$L$154,0)) -> 6 | E13: =INDEX($I$151:$I$154,MATCH($B13,$L$151:$L$154,0)) -> 6 | F13: =INDEX($G$151:$G$154,MATCH($B13,$L$151:$L$154,0)) -> 10 | G13: =INDEX($N$151:$N$154,MATCH($B13,$L$151:$L$154,0)) -> Yes | I13: 1 | J13: =INDEX($B$155:$B$158,MATCH($I13,$L$155:$L$158,0)) -> Netherlands | K13: =INDEX($J$155:$J$158,MATCH($I13,$L$155:$L$158,0)) -> 7 | L13: =INDEX($I$155:$I$158,MATCH($I13,$L$155:$L$158,0)) -> 6 | M13: =INDEX($G$155:$G$158,MATCH($I13,$L$155:$L$158,0)) -> 10 | N13: =INDEX($N$155:$N$158,MATCH($I13,$L$155:$L$158,0)) -> Yes | P13: 1 | Q13: =INDEX($B$159:$B$162,MATCH($P13,$L$159:$L$162,0)) -> Belgium | R13: =INDEX($J$159:$J$162,MATCH($P13,$L$159:$L$162,0)) -> 5 | S13: =INDEX($I$159:$I$162,MATCH($P13,$L$159:$L$162,0)) -> 4 | T13: =INDEX($G$159:$G$162,MATCH($P13,$L$159:$L$162,0)) -> 6 | U13: =INDEX($N$159:$N$162,MATCH($P13,$L$159:$L$162,0)) -> Yes | W13: 1 | X13: =INDEX($B$163:$B$166,MATCH($W13,$L$163:$L$166,0)) -> Spain | Y13: =INDEX($J$163:$J$166,MATCH($W13,$L$163:$L$166,0)) -> 7 | Z13: =INDEX($I$163:$I$166,MATCH($W13,$L$163:$L$166,0)) -> 5 | AA13: =INDEX($G$163:$G$166,MATCH($W13,$L$163:$L$166,0)) -> 5 | AB13: =INDEX($N$163:$N$166,MATCH($W13,$L$163:$L$166,0)) -> Yes
B14: 2 | C14: =INDEX($B$151:$B$154,MATCH($B14,$L$151:$L$154,0)) -> Côte d'Ivoire | D14: =INDEX($J$151:$J$154,MATCH($B14,$L$151:$L$154,0)) -> 6 | E14: =INDEX($I$151:$I$154,MATCH($B14,$L$151:$L$154,0)) -> 2 | F14: =INDEX($G$151:$G$154,MATCH($B14,$L$151:$L$154,0)) -> 4 | G14: =INDEX($N$151:$N$154,MATCH($B14,$L$151:$L$154,0)) -> Yes | I14: 2 | J14: =INDEX($B$155:$B$158,MATCH($I14,$L$155:$L$158,0)) -> Japan | K14: =INDEX($J$155:$J$158,MATCH($I14,$L$155:$L$158,0)) -> 5 | L14: =INDEX($I$155:$I$158,MATCH($I14,$L$155:$L$158,0)) -> 4 | M14: =INDEX($G$155:$G$158,MATCH($I14,$L$155:$L$158,0)) -> 7 | N14: =INDEX($N$155:$N$158,MATCH($I14,$L$155:$L$158,0)) -> Yes | P14: 2 | Q14: =INDEX($B$159:$B$162,MATCH($P14,$L$159:$L$162,0)) -> Egypt | R14: =INDEX($J$159:$J$162,MATCH($P14,$L$159:$L$162,0)) -> 5 | S14: =INDEX($I$159:$I$162,MATCH($P14,$L$159:$L$162,0)) -> 2 | T14: =INDEX($G$159:$G$162,MATCH($P14,$L$159:$L$162,0)) -> 5 | U14: =INDEX($N$159:$N$162,MATCH($P14,$L$159:$L$162,0)) -> Yes | W14: 2 | X14: =INDEX($B$163:$B$166,MATCH($W14,$L$163:$L$166,0)) -> Cabo Verde | Y14: =INDEX($J$163:$J$166,MATCH($W14,$L$163:$L$166,0)) -> 3 | Z14: =INDEX($I$163:$I$166,MATCH($W14,$L$163:$L$166,0)) -> 0 | AA14: =INDEX($G$163:$G$166,MATCH($W14,$L$163:$L$166,0)) -> 2 | AB14: =INDEX($N$163:$N$166,MATCH($W14,$L$163:$L$166,0)) -> Yes
B15: 3 | C15: =INDEX($B$151:$B$154,MATCH($B15,$L$151:$L$154,0)) -> Ecuador | D15: =INDEX($J$151:$J$154,MATCH($B15,$L$151:$L$154,0)) -> 4 | E15: =INDEX($I$151:$I$154,MATCH($B15,$L$151:$L$154,0)) -> 0 | F15: =INDEX($G$151:$G$154,MATCH($B15,$L$151:$L$154,0)) -> 2 | G15: =INDEX($N$151:$N$154,MATCH($B15,$L$151:$L$154,0)) -> Yes | I15: 3 | J15: =INDEX($B$155:$B$158,MATCH($I15,$L$155:$L$158,0)) -> Sweden | K15: =INDEX($J$155:$J$158,MATCH($I15,$L$155:$L$158,0)) -> 4 | L15: =INDEX($I$155:$I$158,MATCH($I15,$L$155:$L$158,0)) -> 0 | M15: =INDEX($G$155:$G$158,MATCH($I15,$L$155:$L$158,0)) -> 7 | N15: =INDEX($N$155:$N$158,MATCH($I15,$L$155:$L$158,0)) -> Yes | P15: 3 | Q15: =INDEX($B$159:$B$162,MATCH($P15,$L$159:$L$162,0)) -> IR Iran | R15: =INDEX($J$159:$J$162,MATCH($P15,$L$159:$L$162,0)) -> 3 | S15: =INDEX($I$159:$I$162,MATCH($P15,$L$159:$L$162,0)) -> 0 | T15: =INDEX($G$159:$G$162,MATCH($P15,$L$159:$L$162,0)) -> 3 | U15: =INDEX($N$159:$N$162,MATCH($P15,$L$159:$L$162,0)) -> No | W15: 3 | X15: =INDEX($B$163:$B$166,MATCH($W15,$L$163:$L$166,0)) -> Uruguay | Y15: =INDEX($J$163:$J$166,MATCH($W15,$L$163:$L$166,0)) -> 2 | Z15: =INDEX($I$163:$I$166,MATCH($W15,$L$163:$L$166,0)) -> -1 | AA15: =INDEX($G$163:$G$166,MATCH($W15,$L$163:$L$166,0)) -> 3 | AB15: =INDEX($N$163:$N$166,MATCH($W15,$L$163:$L$166,0)) -> No
B16: 4 | C16: =INDEX($B$151:$B$154,MATCH($B16,$L$151:$L$154,0)) -> Curaçao | D16: =INDEX($J$151:$J$154,MATCH($B16,$L$151:$L$154,0)) -> 1 | E16: =INDEX($I$151:$I$154,MATCH($B16,$L$151:$L$154,0)) -> -8 | F16: =INDEX($G$151:$G$154,MATCH($B16,$L$151:$L$154,0)) -> 1 | G16: =INDEX($N$151:$N$154,MATCH($B16,$L$151:$L$154,0)) -> No | I16: 4 | J16: =INDEX($B$155:$B$158,MATCH($I16,$L$155:$L$158,0)) -> Tunisia | K16: =INDEX($J$155:$J$158,MATCH($I16,$L$155:$L$158,0)) -> 0 | L16: =INDEX($I$155:$I$158,MATCH($I16,$L$155:$L$158,0)) -> -10 | M16: =INDEX($G$155:$G$158,MATCH($I16,$L$155:$L$158,0)) -> 2 | N16: =INDEX($N$155:$N$158,MATCH($I16,$L$155:$L$158,0)) -> No | P16: 4 | Q16: =INDEX($B$159:$B$162,MATCH($P16,$L$159:$L$162,0)) -> New Zealand | R16: =INDEX($J$159:$J$162,MATCH($P16,$L$159:$L$162,0)) -> 1 | S16: =INDEX($I$159:$I$162,MATCH($P16,$L$159:$L$162,0)) -> -6 | T16: =INDEX($G$159:$G$162,MATCH($P16,$L$159:$L$162,0)) -> 4 | U16: =INDEX($N$159:$N$162,MATCH($P16,$L$159:$L$162,0)) -> No | W16: 4 | X16: =INDEX($B$163:$B$166,MATCH($W16,$L$163:$L$166,0)) -> Saudi Arabia | Y16: =INDEX($J$163:$J$166,MATCH($W16,$L$163:$L$166,0)) -> 2 | Z16: =INDEX($I$163:$I$166,MATCH($W16,$L$163:$L$166,0)) -> -4 | AA16: =INDEX($G$163:$G$166,MATCH($W16,$L$163:$L$166,0)) -> 1 | AB16: =INDEX($N$163:$N$166,MATCH($W16,$L$163:$L$166,0)) -> No
B18: Group I | I18: Group J | P18: Group K | W18: Group L
B19: Pos | C19: Team | D19: Pts | E19: GD | F19: GF | G19: Qualified? | I19: Pos | J19: Team | K19: Pts | L19: GD | M19: GF | N19: Qualified? | P19: Pos | Q19: Team | R19: Pts | S19: GD | T19: GF | U19: Qualified? | W19: Pos | X19: Team | Y19: Pts | Z19: GD | AA19: GF | AB19: Qualified?
B20: 1 | C20: =INDEX($B$167:$B$170,MATCH($B20,$L$167:$L$170,0)) -> France | D20: =INDEX($J$167:$J$170,MATCH($B20,$L$167:$L$170,0)) -> 9 | E20: =INDEX($I$167:$I$170,MATCH($B20,$L$167:$L$170,0)) -> 8 | F20: =INDEX($G$167:$G$170,MATCH($B20,$L$167:$L$170,0)) -> 10 | G20: =INDEX($N$167:$N$170,MATCH($B20,$L$167:$L$170,0)) -> Yes | I20: 1 | J20: =INDEX($B$171:$B$174,MATCH($I20,$L$171:$L$174,0)) -> Argentina | K20: =INDEX($J$171:$J$174,MATCH($I20,$L$171:$L$174,0)) -> 9 | L20: =INDEX($I$171:$I$174,MATCH($I20,$L$171:$L$174,0)) -> 7 | M20: =INDEX($G$171:$G$174,MATCH($I20,$L$171:$L$174,0)) -> 8 | N20: =INDEX($N$171:$N$174,MATCH($I20,$L$171:$L$174,0)) -> Yes | P20: 1 | Q20: =INDEX($B$175:$B$178,MATCH($P20,$L$175:$L$178,0)) -> Colombia | R20: =INDEX($J$175:$J$178,MATCH($P20,$L$175:$L$178,0)) -> 7 | S20: =INDEX($I$175:$I$178,MATCH($P20,$L$175:$L$178,0)) -> 3 | T20: =INDEX($G$175:$G$178,MATCH($P20,$L$175:$L$178,0)) -> 4 | U20: =INDEX($N$175:$N$178,MATCH($P20,$L$175:$L$178,0)) -> Yes | W20: 1 | X20: =INDEX($B$179:$B$182,MATCH($W20,$L$179:$L$182,0)) -> England | Y20: =INDEX($J$179:$J$182,MATCH($W20,$L$179:$L$182,0)) -> 7 | Z20: =INDEX($I$179:$I$182,MATCH($W20,$L$179:$L$182,0)) -> 4 | AA20: =INDEX($G$179:$G$182,MATCH($W20,$L$179:$L$182,0)) -> 6 | AB20: =INDEX($N$179:$N$182,MATCH($W20,$L$179:$L$182,0)) -> Yes
B21: 2 | C21: =INDEX($B$167:$B$170,MATCH($B21,$L$167:$L$170,0)) -> Norway | D21: =INDEX($J$167:$J$170,MATCH($B21,$L$167:$L$170,0)) -> 6 | E21: =INDEX($I$167:$I$170,MATCH($B21,$L$167:$L$170,0)) -> 1 | F21: =INDEX($G$167:$G$170,MATCH($B21,$L$167:$L$170,0)) -> 8 | G21: =INDEX($N$167:$N$170,MATCH($B21,$L$167:$L$170,0)) -> Yes | I21: 2 | J21: =INDEX($B$171:$B$174,MATCH($I21,$L$171:$L$174,0)) -> Austria | K21: =INDEX($J$171:$J$174,MATCH($I21,$L$171:$L$174,0)) -> 4 | L21: =INDEX($I$171:$I$174,MATCH($I21,$L$171:$L$174,0)) -> 0 | M21: =INDEX($G$171:$G$174,MATCH($I21,$L$171:$L$174,0)) -> 6 | N21: =INDEX($N$171:$N$174,MATCH($I21,$L$171:$L$174,0)) -> Yes | P21: 2 | Q21: =INDEX($B$175:$B$178,MATCH($P21,$L$175:$L$178,0)) -> Portugal | R21: =INDEX($J$175:$J$178,MATCH($P21,$L$175:$L$178,0)) -> 5 | S21: =INDEX($I$175:$I$178,MATCH($P21,$L$175:$L$178,0)) -> 5 | T21: =INDEX($G$175:$G$178,MATCH($P21,$L$175:$L$178,0)) -> 6 | U21: =INDEX($N$175:$N$178,MATCH($P21,$L$175:$L$178,0)) -> Yes | W21: 2 | X21: =INDEX($B$179:$B$182,MATCH($W21,$L$179:$L$182,0)) -> Croatia | Y21: =INDEX($J$179:$J$182,MATCH($W21,$L$179:$L$182,0)) -> 6 | Z21: =INDEX($I$179:$I$182,MATCH($W21,$L$179:$L$182,0)) -> 0 | AA21: =INDEX($G$179:$G$182,MATCH($W21,$L$179:$L$182,0)) -> 5 | AB21: =INDEX($N$179:$N$182,MATCH($W21,$L$179:$L$182,0)) -> Yes
B22: 3 | C22: =INDEX($B$167:$B$170,MATCH($B22,$L$167:$L$170,0)) -> Senegal | D22: =INDEX($J$167:$J$170,MATCH($B22,$L$167:$L$170,0)) -> 3 | E22: =INDEX($I$167:$I$170,MATCH($B22,$L$167:$L$170,0)) -> 2 | F22: =INDEX($G$167:$G$170,MATCH($B22,$L$167:$L$170,0)) -> 8 | G22: =INDEX($N$167:$N$170,MATCH($B22,$L$167:$L$170,0)) -> Yes | I22: 3 | J22: =INDEX($B$171:$B$174,MATCH($I22,$L$171:$L$174,0)) -> Algeria | K22: =INDEX($J$171:$J$174,MATCH($I22,$L$171:$L$174,0)) -> 4 | L22: =INDEX($I$171:$I$174,MATCH($I22,$L$171:$L$174,0)) -> -2 | M22: =INDEX($G$171:$G$174,MATCH($I22,$L$171:$L$174,0)) -> 5 | N22: =INDEX($N$171:$N$174,MATCH($I22,$L$171:$L$174,0)) -> Yes | P22: 3 | Q22: =INDEX($B$175:$B$178,MATCH($P22,$L$175:$L$178,0)) -> Congo DR | R22: =INDEX($J$175:$J$178,MATCH($P22,$L$175:$L$178,0)) -> 4 | S22: =INDEX($I$175:$I$178,MATCH($P22,$L$175:$L$178,0)) -> 1 | T22: =INDEX($G$175:$G$178,MATCH($P22,$L$175:$L$178,0)) -> 4 | U22: =INDEX($N$175:$N$178,MATCH($P22,$L$175:$L$178,0)) -> Yes | W22: 3 | X22: =INDEX($B$179:$B$182,MATCH($W22,$L$179:$L$182,0)) -> Ghana | Y22: =INDEX($J$179:$J$182,MATCH($W22,$L$179:$L$182,0)) -> 4 | Z22: =INDEX($I$179:$I$182,MATCH($W22,$L$179:$L$182,0)) -> 0 | AA22: =INDEX($G$179:$G$182,MATCH($W22,$L$179:$L$182,0)) -> 2 | AB22: =INDEX($N$179:$N$182,MATCH($W22,$L$179:$L$182,0)) -> Yes
B23: 4 | C23: =INDEX($B$167:$B$170,MATCH($B23,$L$167:$L$170,0)) -> Iraq | D23: =INDEX($J$167:$J$170,MATCH($B23,$L$167:$L$170,0)) -> 0 | E23: =INDEX($I$167:$I$170,MATCH($B23,$L$167:$L$170,0)) -> -11 | F23: =INDEX($G$167:$G$170,MATCH($B23,$L$167:$L$170,0)) -> 1 | G23: =INDEX($N$167:$N$170,MATCH($B23,$L$167:$L$170,0)) -> No | I23: 4 | J23: =INDEX($B$171:$B$174,MATCH($I23,$L$171:$L$174,0)) -> Jordan | K23: =INDEX($J$171:$J$174,MATCH($I23,$L$171:$L$174,0)) -> 0 | L23: =INDEX($I$171:$I$174,MATCH($I23,$L$171:$L$174,0)) -> -5 | M23: =INDEX($G$171:$G$174,MATCH($I23,$L$171:$L$174,0)) -> 3 | N23: =INDEX($N$171:$N$174,MATCH($I23,$L$171:$L$174,0)) -> No | P23: 4 | Q23: =INDEX($B$175:$B$178,MATCH($P23,$L$175:$L$178,0)) -> Uzbekistan | R23: =INDEX($J$175:$J$178,MATCH($P23,$L$175:$L$178,0)) -> 0 | S23: =INDEX($I$175:$I$178,MATCH($P23,$L$175:$L$178,0)) -> -9 | T23: =INDEX($G$175:$G$178,MATCH($P23,$L$175:$L$178,0)) -> 2 | U23: =INDEX($N$175:$N$178,MATCH($P23,$L$175:$L$178,0)) -> No | W23: 4 | X23: =INDEX($B$179:$B$182,MATCH($W23,$L$179:$L$182,0)) -> Panama | Y23: =INDEX($J$179:$J$182,MATCH($W23,$L$179:$L$182,0)) -> 0 | Z23: =INDEX($I$179:$I$182,MATCH($W23,$L$179:$L$182,0)) -> -4 | AA23: =INDEX($G$179:$G$182,MATCH($W23,$L$179:$L$182,0)) -> 0 | AB23: =INDEX($N$179:$N$182,MATCH($W23,$L$179:$L$182,0)) -> No
A31: Knockout results | B31: Knockout results | C31: Knockout results | D31: Knockout results | E31: Knockout results | F31: Knockout results | G31: Knockout results | H31: Knockout results | I31: Knockout results | J31: Knockout results | K31: Knockout results | L31: Knockout results | M31: Knockout results | N31: Knockout results | O31: Knockout results | P31: Knockout results | Q31: Knockout results | R31: Knockout results
B38: Round of 32 | E38: Round of 16 | H38: Quarter-finals | K38: Semi-finals | N38: Third-place match | Q38: Final
B39: Match | C39: Winner | E39: Match | F39: Winner | H39: Match | I39: Winner | K39: Match | L39: Winner | N39: Match | O39: Winner | Q39: Result | R39: Team
B40: Germany / Paraguay | C40: =F209 -> Paraguay | E40: Paraguay / France | F40: =F227 -> France | H40: Quarter-final Match 1 | I40: =F239 | K40: Semi-final Match 1 | L40: =F247 | N40: Third-place Match | O40: =F253 | Q40: Champion | R40: =F259
B41: France / Sweden | C41: =F212 -> France | E41: Canada / Morocco | F41: =F228 -> Morocco | H41: Quarter-final Match 2 | I41: =F240 | K41: Semi-final Match 2 | L41: =F248 | Q41: Runner-up | R41: =G259
B42: South Africa / Canada | C42: =F207 -> Canada | E42: Portugal-Croatia / Spain-Austria | F42: =F229 | H42: Quarter-final Match 3 | I42: =F241
B43: Netherlands / Morocco | C43: =F210 -> Morocco | E43: USA-Bosnia / Belgium-Senegal | F43: =F230 | H43: Quarter-final Match 4 | I43: =F242
B44: Portugal / Croatia | C44: =F218 -> Portugal | E44: Brazil / Norway | F44: =F231 -> Norway
B45: Spain / Austria | C45: =F217 -> Spain | E45: Mexico / England-Congo DR | F45: =F232 -> England
B46: USA / Bosnia and Herzegovina | C46: =F216 -> United States | E46: Argentina-Cabo Verde / Australia-Egypt | F46: =F233
B47: Belgium / Senegal | C47: =F215 -> Belgium | E47: Switzerland-Algeria / Colombia-Ghana | F47: =F234
B48: Brazil / Japan | C48: =F208 -> Brazil
B49: Côte d'Ivoire / Norway | C49: =F211 -> Norway
B50: Mexico / Ecuador | C50: =F213 -> Mexico
B51: England / Congo DR | C51: =F214 -> England
B52: Argentina / Cabo Verde | C52: =F221 -> Argentina
B53: Australia / Egypt | C53: =F220 -> Egypt
B54: Switzerland / Algeria | C54: =F219 -> Switzerland
B55: Colombia / Ghana | C55: =F222 -> Colombia
A57: Group Stage Fixtures - enter scores only in Score 1 / Score 2
...

Sheet Group Stage Predictions
A1: Group Stage Predictions
C3: Group A | H3: Group B | M3: Group C | R3: Group D | W3: Group E | AB3: Group F | AG3: Group G | AL3: Group H | AQ3: Group I | AV3: Group J | BA3: Group K | BF3: Group L
A4: Enter predicted 1st, 2nd, and advancing 3rd-place teams for each group. Use the drop-down team list.
A5: Player | C5: 1st | D5: 2nd | E5: 3rd | F5: Pts | G5: Corr | H5: 1st | I5: 2nd | J5: 3rd | K5: Pts | L5: Corr | M5: 1st | N5: 2nd | O5: 3rd | P5: Pts | Q5: Corr | R5: 1st | S5: 2nd | T5: 3rd | U5: Pts | V5: Corr | W5: 1st | X5: 2nd | Y5: 3rd | Z5: Pts | AA5: Corr | AB5: 1st | AC5: 2nd | AD5: 3rd | AE5: Pts | AF5: Corr | AG5: 1st | AH5: 2nd | AI5: 3rd | AJ5: Pts | AK5: Corr | AL5: 1st | AM5: 2nd | AN5: 3rd | AO5: Pts | AP5: Corr | AQ5: 1st | AR5: 2nd | AS5: 3rd | AT5: Pts | AU5: Corr | AV5: 1st | AW5: 2nd | AX5: 3rd | AY5: Pts | AZ5: Corr | BA5: 1st | BB5: 2nd | BC5: 3rd | BD5: Pts | BE5: Corr | BF5: 1st | BG5: 2nd | BH5: 3rd | BI5: Pts | BJ5: Corr | BK5: Group Pts | BL5: Group Corr | BM5: Completion %
A6: =IF(Players!B6="","",Players!B6) -> Febby Yudhi Pratama | C6: Mexico | D6: Korea Republic | E6: South Africa | F6: =IF(AND(C6<>"",'Official Results'!C6<>""),IF(C6='Official Results'!C6,'Instructions & Rules'!$K$4,IF(C6='Official Results'!C7,'Instructions & Rules'!$K$6,0)),0)+IF(AND(D6<>"",'Official Results'!C7<>""),IF(D6='Official Results'!C7,'Instructions & Rules'!$K$5,IF(D6='Official Results'!C6,'Instructions & Rules'!$K$6,0)),0)+IF(AND(E6<>"",'Official Results'!C8<>"",'Official Results'!G8="Yes"),IF(E6='Official Results'!C8,'Instructions & Rules'!$K$7,0),0)+IF(AND(C6='Official Results'!C6,D6='Official Results'!C7,'Official Results'!C6<>"",'Official Results'!C7<>""),'Instructions & Rules'!$K$8,0)+IF(AND(C6='Official Results'!C6,D6='Official Results'!C7,E6='Official Results'!C8,'Official Results'!G8="Yes"),'Instructions & Rules'!$K$9,0) -> 4 | G6: =IF(AND(C6<>"",'Official Results'!C6<>"",C6='Official Results'!C6),1,0)+IF(AND(D6<>"",'Official Results'!C7<>"",D6='Official Results'!C7),1,0)+IF(AND(E6<>"",'Official Results'!C8<>"",'Official Results'!G8="Yes",E6='Official Results'!C8),1,0) -> 1 | H6: Switzerland | I6: Canada | J6: Bosnia and Herzegovina | K6: =IF(AND(H6<>"",'Official Results'!J6<>""),IF(H6='Official Results'!J6,'Instructions & Rules'!$K$4,IF(H6='Official Results'!J7,'Instructions & Rules'!$K$6,0)),0)+IF(AND(I6<>"",'Official Results'!J7<>""),IF(I6='Official Results'!J7,'Instructions & Rules'!$K$5,IF(I6='Official Results'!J6,'Instructions & Rules'!$K$6,0)),0)+IF(AND(J6<>"",'Official Results'!J8<>"",'Official Results'!N8="Yes"),IF(J6='Official Results'!J8,'Instructions & Rules'!$K$7,0),0)+IF(AND(H6='Official Results'!J6,I6='Official Results'!J7,'Official Results'!J6<>"",'Official Results'!J7<>""),'Instructions & Rules'!$K$8,0)+IF(AND(H6='Official Results'!J6,I6='Official Results'!J7,J6='Official Results'!J8,'Official Results'!N8="Yes"),'Instructions & Rules'!$K$9,0) -> 15 | L6: =IF(AND(H6<>"",'Official Results'!J6<>"",H6='Official Results'!J6),1,0)+IF(AND(I6<>"",'Official Results'!J7<>"",I6='Official Results'!J7),1,0)+IF(AND(J6<>"",'Official Results'!J8<>"",'Official Results'!N8="Yes",J6='Official Results'!J8),1,0) -> 3 | M6: Brazil | N6: Morocco | O6: Scotland | P6: =IF(AND(M6<>"",'Official Results'!Q6<>""),IF(M6='Official Results'!Q6,'Instructions & Rules'!$K$4,IF(M6='Official Results'!Q7,'Instructions & Rules'!$K$6,0)),0)+IF(AND(N6<>"",'Official Results'!Q7<>""),IF(N6='Official Results'!Q7,'Instructions & Rules'!$K$5,IF(N6='Official Results'!Q6,'Instructions & Rules'!$K$6,0)),0)+IF(AND(O6<>"",'Official Results'!Q8<>"",'Official Results'!U8="Yes"),IF(O6='Official Results'!Q8,'Instructions & Rules'!$K$7,0),0)+IF(AND(M6='Official Results'!Q6,N6='Official Results'!Q7,'Official Results'!Q6<>"",'Official Results'!Q7<>""),'Instructions & Rules'!$K$8,0)+IF(AND(M6='Official Results'!Q6,N6='Official Results'!Q7,O6='Official Results'!Q8,'Official Results'!U8="Yes"),'Instructions & Rules'!$K$9,0) -> 10 | Q6: =IF(AND(M6<>"",'Official Results'!Q6<>"",M6='Official Results'!Q6),1,0)+IF(AND(N6<>"",'Official Results'!Q7<>"",N6='Official Results'!Q7),1,0)+IF(AND(O6<>"",'Official Results'!Q8<>"",'Official Results'!U8="Yes",O6='Official Results'!Q8),1,0) -> 2 | R6: Türkiye | S6: United States | T6: Australia | U6: =IF(AND(R6<>"",'Official Results'!X6<>""),IF(R6='Official Results'!X6,'Instructions & Rules'!$K$4,IF(R6='Official Results'!X7,'Instructions & Rules'!$K$6,0)),0)+IF(AND(S6<>"",'Official Results'!X7<>""),IF(S6='Official Results'!X7,'Instructions & Rules'!$K$5,IF(S6='Official Results'!X6,'Instructions & Rules'!$K$6,0)),0)+IF(AND(T6<>"",'Official Results'!X8<>"",'Official Results'!AB8="Yes"),IF(T6='Official Results'!X8,'Instructions & Rules'!$K$7,0),0)+IF(AND(R6='Official Results'!X6,S6='Official Results'!X7,'Official Results'!X6<>"",'Official Results'!X7<>""),'Instructions & Rules'!$K$8,0)+IF(AND(R6='Official Results'!X6,S6='Official Results'!X7,T6='Official Results'!X8,'Official Results'!AB8="Yes"),'Instructions & Rules'!$K$9,0) -> 1 | V6: =IF(AND(R6<>"",'Official Results'!X6<>"",R6='Official Results'!X6),1,0)+IF(AND(S6<>"",'Official Results'!X7<>"",S6='Official Results'!X7),1,0)+IF(AND(T6<>"",'Official Results'!X8<>"",'Official Results'!AB8="Yes",T6='Official Results'!X8),1,0) -> 0 | W6: Germany | X6: Côte d'Ivoire | Y6: Ecuador | Z6: =IF(AND(W6<>"",'Official Results'!C13<>""),IF(W6='Official Results'!C13,'Instructions & Rules'!$K$4,IF(W6='Official Results'!C14,'Instructions & Rules'!$K$6,0)),0)+IF(AND(X6<>"",'Official Results'!C14<>""),IF(X6='Official Results'!C14,'Instructions & Rules'!$K$5,IF(X6='Official Results'!C13,'Instructions & Rules'!$K$6,0)),0)+IF(AND(Y6<>"",'Official Results'!C15<>"",'Official Results'!G15="Yes"),IF(Y6='Official Results'!C15,'Instructions & Rules'!$K$7,0),0)+IF(AND(W6='Official Results'!C13,X6='Official Results'!C14,'Official Results'!C13<>"",'Official Results'!C14<>""),'Instructions & Rules'!$K$8,0)+IF(AND(W6='Official Results'!C13,X6='Official Results'!C14,Y6='Official Results'!C15,'Official Results'!G15="Yes"),'Instructions & Rules'!$K$9,0) -> 15 | AA6: =IF(AND(W6<>"",'Official Results'!C13<>"",W6='Official Results'!C13),1,0)+IF(AND(X6<>"",'Official Results'!C14<>"",X6='Official Results'!C14),1,0)+IF(AND(Y6<>"",'Official Results'!C15<>"",'Official Results'!G15="Yes",Y6='Official Results'!C15),1,0) -> 3 | AB6: Netherlands | AC6: Japan | AD6: Sweden | AE6: =IF(AND(AB6<>"",'Official Results'!J13<>""),IF(AB6='Official Results'!J13,'Instructions & Rules'!$K$4,IF(AB6='Official Results'!J14,'Instructions & Rules'!$K$6,0)),0)+IF(AND(AC6<>"",'Official Results'!J14<>""),IF(AC6='Official Results'!J14,'Instructions & Rules'!$K$5,IF(AC6='Official Results'!J13,'Instructions & Rules'!$K$6,0)),0)+IF(AND(AD6<>"",'Official Results'!J15<>"",'Official Results'!N15="Yes"),IF(AD6='Official Results'!J15,'Instructions & Rules'!$K$7,0),0)+IF(AND(AB6='Official Results'!J13,AC6='Official Results'!J14,'Official Results'!J13<>"",'Official Results'!J14<>""),'Instructions & Rules'!$K$8,0)+IF(AND(AB6='Official Results'!J13,AC6='Official Results'!J14,AD6='Official Results'!J15,'Official Results'!N15="Yes"),'Instructions & Rules'!$K$9,0) -> 15 | AF6: =IF(AND(AB6<>"",'Official Results'!J13<>"",AB6='Official Results'!J13),1,0)+IF(AND(AC6<>"",'Official Results'!J14<>"",AC6='Official Results'!J14),1,0)+IF(AND(AD6<>"",'Official Results'!J15<>"",'Official Results'!N15="Yes",AD6='Official Results'!J15),1,0) -> 3 | AG6: Belgium | AH6: Egypt | AI6: IR Iran | AJ6: =IF(AND(AG6<>"",'Official Results'!Q13<>""),IF(AG6='Official Results'!Q13,'Instructions & Rules'!$K$4,IF(AG6='Official Results'!Q14,'Instructions & Rules'!$K$6,0)),0)+IF(AND(AH6<>"",'Official Results'!Q14<>""),IF(AH6='Official Results'!Q14,'Instructions & Rules'!$K$5,IF(AH6='Official Results'!Q13,'Instructions & Rules'!$K$6,0)),0)+IF(AND(AI6<>"",'Official Results'!Q15<>"",'Official Results'!U15="Yes"),IF(AI6='Official Results'!Q15,'Instructions & Rules'!$K$7,0),0)+IF(AND(AG6='Official Results'!Q13,AH6='Official Results'!Q14,'Official Results'!Q13<>"",'Official Results'!Q14<>""),'Instructions & Rules'!$K$8,0)+IF(AND(AG6='Official Results'!Q13,AH6='Official Results'!Q14,AI6='Official Results'!Q15,'Official Results'!U15="Yes"),'Instructions & Rules'!$K$9,0) -> 10 | AK6: =IF(AND(AG6<>"",'Official Results'!Q13<>"",AG6='Official Results'!Q13),1,0)+IF(AND(AH6<>"",'Official Results'!Q14<>"",AH6='Official Results'!Q14),1,0)+IF(AND(AI6<>"",'Official Results'!Q15<>"",'Official Results'!U15="Yes",AI6='Official Results'!Q15),1,0) -> 2 | AL6: Spain | AM6: Uruguay | AN6: Saudi Arabia | AO6: =IF(AND(AL6<>"",'Official Results'!X13<>""),IF(AL6='Official Results'!X13,'Instructions & Rules'!$K$4,IF(AL6='Official Results'!X14,'Instructions & Rules'!$K$6,0)),0)+IF(AND(AM6<>"",'Official Results'!X14<>""),IF(AM6='Official Results'!X14,'Instructions & Rules'!$K$5,IF(AM6='Official Results'!X13,'Instructions & Rules'!$K$6,0)),0)+IF(AND(AN6<>"",'Official Results'!X15<>"",'Official Results'!AB15="Yes"),IF(AN6='Official Results'!X15,'Instructions & Rules'!$K$7,0),0)+IF(AND(AL6='Official Results'!X13,AM6='Official Results'!X14,'Official Results'!X13<>"",'Official Results'!X14<>""),'Instructions & Rules'!$K$8,0)+IF(AND(AL6='Official Results'!X13,AM6='Official Results'!X14,AN6='Official Results'!X15,'Official Results'!AB15="Yes"),'Instructions & Rules'!$K$9,0) -> 4 | AP6: =IF(AND(AL6<>"",'Official Results'!X13<>"",AL6='Official Results'!X13),1,0)+IF(AND(AM6<>"",'Official Results'!X14<>"",AM6='Official Results'!X14),1,0)+IF(AND(AN6<>"",'Official Results'!X15<>"",'Official Results'!AB15="Yes",AN6='Official Results'!X15),1,0) -> 1 | AQ6: France | AR6: Norway | AS6: Iraq | AT6: =IF(AND(AQ6<>"",'Official Results'!C20<>""),IF(AQ6='Official Results'!C20,'Instructions & Rules'!$K$4,IF(AQ6='Official Results'!C21,'Instructions & Rules'!$K$6,0)),0)+IF(AND(AR6<>"",'Official Results'!C21<>""),IF(AR6='Official Results'!C21,'Instructions & Rules'!$K$5,IF(AR6='Official Results'!C20,'Instructions & Rules'!$K$6,0)),0)+IF(AND(AS6<>"",'Official Results'!C22<>"",'Official Results'!G22="Yes"),IF(AS6='Official Results'!C22,'Instructions & Rules'!$K$7,0),0)+IF(AND(AQ6='Official Results'!C20,AR6='Official Results'!C21,'Official Results'!C20<>"",'Official Results'!C21<>""),'Instructions & Rules'!$K$8,0)+IF(AND(AQ6='Official Results'!C20,AR6='Official Results'!C21,AS6='Official Results'!C22,'Official Results'!G22="Yes"),'Instructions & Rules'!$K$9,0) -> 10 | AU6: =IF(AND(AQ6<>"",'Official Results'!C20<>"",AQ6='Official Results'!C20),1,0)+IF(AND(AR6<>"",'Official Results'!C21<>"",AR6='Official Results'!C21),1,0)+IF(AND(AS6<>"",'Official Results'!C22<>"",'Official Results'!G22="Yes",AS6='Official Results'!C22),1,0) -> 2 | AV6: Argentina | AW6: Algeria | AX6: Austria | AY6: =IF(AND(AV6<>"",'Official Results'!J20<>""),IF(AV6='Official Results'!J20,'Instructions & Rules'!$K$4,IF(AV6='Official Results'!J21,'Instructions & Rules'!$K$6,0)),0)+IF(AND(AW6<>"",'Official Results'!J21<>""),IF(AW6='Official Results'!J21,'Instructions & Rules'!$K$5,IF(AW6='Official Results'!J20,'Instructions & Rules'!$K$6,0)),0)+IF(AND(AX6<>"",'Official Results'!J22<>"",'Official Results'!N22="Yes"),IF(AX6='Official Results'!J22,'Instructions & Rules'!$K$7,0),0)+IF(AND(AV6='Official Results'!J20,AW6='Official Results'!J21,'Official Results'!J20<>"",'Official Results'!J21<>""),'Instructions & Rules'!$K$8,0)+IF(AND(AV6='Official Results'!J20,AW6='Official Results'!J21,AX6='Official Results'!J22,'Official Results'!N22="Yes"),'Instructions & Rules'!$K$9,0) -> 4 | AZ6: =IF(AND(AV6<>"",'Official Results'!J20<>"",AV6='Official Results'!J20),1,0)+IF(AND(AW6<>"",'Official Results'!J21<>"",AW6='Official Results'!J21),1,0)+IF(AND(AX6<>"",'Official Results'!J22<>"",'Official Results'!N22="Yes",AX6='Official Results'!J22),1,0) -> 1 | BA6: Portugal | BB6: Colombia | BC6: Uzbekistan | BD6: =IF(AND(BA6<>"",'Official Results'!Q20<>""),IF(BA6='Official Results'!Q20,'Instructions & Rules'!$K$4,IF(BA6='Official Results'!Q21,'Instructions & Rules'!$K$6,0)),0)+IF(AND(BB6<>"",'Official Results'!Q21<>""),IF(BB6='Official Results'!Q21,'Instructions & Rules'!$K$5,IF(BB6='Official Results'!Q20,'Instructions & Rules'!$K$6,0)),0)+IF(AND(BC6<>"",'Official Results'!Q22<>"",'Official Results'!U22="Yes"),IF(BC6='Official Results'!Q22,'Instructions & Rules'!$K$7,0),0)+IF(AND(BA6='Official Results'!Q20,BB6='Official Results'!Q21,'Official Results'!Q20<>"",'Official Results'!Q21<>""),'Instructions & Rules'!$K$8,0)+IF(AND(BA6='Official Results'!Q20,BB6='Official Results'!Q21,BC6='Official Results'!Q22,'Official Results'!U22="Yes"),'Instructions & Rules'!$K$9,0) -> 2 | BE6: =IF(AND(BA6<>"",'Official Results'!Q20<>"",BA6='Official Results'!Q20),1,0)+IF(AND(BB6<>"",'Official Results'!Q21<>"",BB6='Official Results'!Q21),1,0)+IF(AND(BC6<>"",'Official Results'!Q22<>"",'Official Results'!U22="Yes",BC6='Official Results'!Q22),1,0) -> 0 | BF6: England | BG6: Croatia | BH6: Ghana | BI6: =IF(AND(BF6<>"",'Official Results'!X20<>""),IF(BF6='Official Results'!X20,'Instructions & Rules'!$K$4,IF(BF6='Official Results'!X21,'Instructions & Rules'!$K$6,0)),0)+IF(AND(BG6<>"",'Official Results'!X21<>""),IF(BG6='Official Results'!X21,'Instructions & Rules'!$K$5,IF(BG6='Official Results'!X20,'Instructions & Rules'!$K$6,0)),0)+IF(AND(BH6<>"",'Official Results'!X22<>"",'Official Results'!AB22="Yes"),IF(BH6='Official Results'!X22,'Instructions & Rules'!$K$7,0),0)+IF(AND(BF6='Official Results'!X20,BG6='Official Results'!X21,'Official Results'!X20<>"",'Official Results'!X21<>""),'Instructions & Rules'!$K$8,0)+IF(AND(BF6='Official Results'!X20,BG6='Official Results'!X21,BH6='Official Results'!X22,'Official Results'!AB22="Yes"),'Instructions & Rules'!$K$9,0) -> 15 | BJ6: =IF(AND(BF6<>"",'Official Results'!X20<>"",BF6='Official Results'!X20),1,0)+IF(AND(BG6<>"",'Official Results'!X21<>"",BG6='Official Results'!X21),1,0)+IF(AND(BH6<>"",'Official Results'!X22<>"",'Official Results'!AB22="Yes",BH6='Official Results'!X22),1,0) -> 3 | BK6: =SUM(F6,K6,P6,U6,Z6,AE6,AJ6,AO6,AT6,AY6,BD6,BI6) -> 105 | BL6: =SUM(G6,L6,Q6,V6,AA6,AF6,AK6,AP6,AU6,AZ6,BE6,BJ6) -> 21 | BM6: =SUM(COUNTIF(C6:E6,"<>"),COUNTIF(H6:J6,"<>"),COUNTIF(M6:O6,"<>"),COUNTIF(R6:T6,"<>"),COUNTIF(W6:Y6,"<>"),COUNTIF(AB6:AD6,"<>"),COUNTIF(AG6:AI6,"<>"),COUNTIF(AL6:AN6,"<>"),COUNTIF(AQ6:AS6,"<>"),COUNTIF(AV6:AX6,"<>"),COUNTIF(BA6:BC6,"<>"),COUNTIF(BF6:BH6,"<>"))/36 -> 1
A7: =IF(Players!B7="","",Players!B7) -> Fathan Mauludin | C7: Mexico | D7: Czechia | E7: Korea Republic | F7: =IF(AND(C7<>"",'Official Results'!C6<>""),IF(C7='Official Results'!C6,'Instructions & Rules'!$K$4,IF(C7='Official Results'!C7,'Instructions & Rules'!$K$6,0)),0)+IF(AND(D7<>"",'Official Results'!C7<>""),IF(D7='Official Results'!C7,'Instructions & Rules'!$K$5,IF(D7='Official Results'!C6,'Instructions & Rules'!$K$6,0)),0)+IF(AND(E7<>"",'Official Results'!C8<>"",'Official Results'!G8="Yes"),IF(E7='Official Results'!C8,'Instructions & Rules'!$K$7,0),0)+IF(AND(C7='Official Results'!C6,D7='Official Results'!C7,'Official Results'!C6<>"",'Official Results'!C7<>""),'Instructions & Rules'!$K$8,0)+IF(AND(C7='Official Results'!C6,D7='Official Results'!C7,E7='Official Results'!C8,'Official Results'!G8="Yes"),'Instructions & Rules'!$K$9,0) -> 4 | G7: =IF(AND(C7<>"",'Official Results'!C6<>"",C7='Official Results'!C6),1,0)+IF(AND(D7<>"",'Official Results'!C7<>"",D7='Official Results'!C7),1,0)+IF(AND(E7<>"",'Official Results'!C8<>"",'Official Results'!G8="Yes",E7='Official Results'!C8),1,0) -> 1 | H7: Switzerland | I7: Canada | J7: Qatar | K7: =IF(AND(H7<>"",'Official Results'!J6<>""),IF(H7='Official Results'!J6,'Instructions & Rules'!$K$4,IF(H7='Official Results'!J7,'Instructions & Rules'!$K$6,0)),0)+IF(AND(I7<>"",'Official Results'!J7<>""),IF(I7='Official Results'!J7,'Instructions & Rules'!$K$5,IF(I7='Official Results'!J6,'Instructions & Rules'!$K$6,0)),0)+IF(AND(J7<>"",'Official Results'!J8<>"",'Official Results'!N8="Yes"),IF(J7='Official Results'!J8,'Instructions & Rules'!$K$7,0),0)+IF(AND(H7='Official Results'!J6,I7='Official Results'!J7,'Official Results'!J6<>"",'Official Results'!J7<>""),'Instructions & Rules'!$K$8,0)+IF(AND(H7='Official Results'!J6,I7='Official Results'!J7,J7='Official Results'!J8,'Official Results'!N8="Yes"),'Instructions & Rules'!$K$9,0) -> 10 | L7: =IF(AND(H7<>"",'Official Results'!J6<>"",H7='Official Results'!J6),1,0)+IF(AND(I7<>"",'Official Results'!J7<>"",I7='Official Results'!J7),1,0)+IF(AND(J7<>"",'Official Results'!J8<>"",'Official Results'!N8="Yes",J7='Official Results'!J8),1,0) -> 2 | M7: Brazil | N7: Scotland | O7: Morocco | P7: =IF(AND(M7<>"",'Official Results'!Q6<>""),IF(M7='Official Results'!Q6,'Instructions & Rules'!$K$4,IF(M7='Official Results'!Q7,'Instructions & Rules'!$K$6,0)),0)+IF(AND(N7<>"",'Official Results'!Q7<>""),IF(N7='Official Results'!Q7,'Instructions & Rules'!$K$5,IF(N7='Official Results'!Q6,'Instructions & Rules'!$K$6,0)),0)+IF(AND(O7<>"",'Official Results'!Q8<>"",'Official Results'!U8="Yes"),IF(O7='Official Results'!Q8,'Instructions & Rules'!$K$7,0),0)+IF(AND(M7='Official Results'!Q6,N7='Official Results'!Q7,'Official Results'!Q6<>"",'Official Results'!Q7<>""),'Instructions & Rules'!$K$8,0)+IF(AND(M7='Official Results'!Q6,N7='Official Results'!Q7,O7='Official Results'!Q8,'Official Results'!U8="Yes"),'Instructions & Rules'!$K$9,0) -> 4 | Q7: =IF(AND(M7<>"",'Official Results'!Q6<>"",M7='Official Results'!Q6),1,0)+IF(AND(N7<>"",'Official Results'!Q7<>"",N7='Official Results'!Q7),1,0)+IF(AND(O7<>"",'Official Results'!Q8<>"",'Official Results'!U8="Yes",O7='Official Results'!Q8),1,0) -> 1 | R7: Türkiye | S7: United States | T7: Australia | U7: =IF(AND(R7<>"",'Official Results'!X6<>""),IF(R7='Official Results'!X6,'Instructions & Rules'!$K$4,IF(R7='Official Results'!X7,'Instructions & Rules'!$K$6,0)),0)+IF(AND(S7<>"",'Official Results'!X7<>""),IF(S7='Official Results'!X7,'Instructions & Rules'!$K$5,IF(S7='Official Results'!X6,'Instructions & Rules'!$K$6,0)),0)+IF(AND(T7<>"",'Official Results'!X8<>"",'Official Results'!AB8="Yes"),IF(T7='Official Results'!X8,'Instructions & Rules'!$K$7,0),0)+IF(AND(R7='Official Results'!X6,S7='Official Results'!X7,'Official Results'!X6<>"",'Official Results'!X7<>""),'Instructions & Rules'!$K$8,0)+IF(AND(R7='Official Results'!X6,S7='Official Results'!X7,T7='Official Results'!X8,'Official Results'!AB8="Yes"),'Instructions & Rules'!$K$9,0) -> 1 | V7: =IF(AND(R7<>"",'Official Results'!X6<>"",R7='Official Results'!X6),1,0)+IF(AND(S7<>"",'Official Results'!X7<>"",S7='Official Results'!X7),1,0)+IF(AND(T7<>"",'Official Results'!X8<>"",'Official Results'!AB8="Yes",T7='Official Results'!X8),1,0) -> 0 | W7: Germany | X7: Côte d'Ivoire | Y7: Ecuador | Z7: =IF(AND(W7<>"",'Official Results'!C13<>""),IF(W7='Official Results'!C13,'Instructions & Rules'!$K$4,IF(W7='Official Results'!C14,'Instructions & Rules'!$K$6,0)),0)+IF(AND(X7<>"",'Official Results'!C14<>""),IF(X7='Official Results'!C14,'Instructions & Rules'!$K$5,IF(X7='Official Results'!C13,'Instructions & Rules'!$K$6,0)),0)+IF(AND(Y7<>"",'Official Results'!C15<>"",'Official Results'!G15="Yes"),IF(Y7='Official Results'!C15,'Instructions & Rules'!$K$7,0),0)+IF(AND(W7='Official Results'!C13,X7='Official Results'!C14,'Official Results'!C13<>"",'Official Results'!C14<>""),'Instructions & Rules'!$K$8,0)+IF(AND(W7='Official Results'!C13,X7='Official Results'!C14,Y7='Official Results'!C15,'Official Results'!G15="Yes"),'Instructions & Rules'!$K$9,0) -> 15 | AA7: =IF(AND(W7<>"",'Official Results'!C13<>"",W7='Official Results'!C13),1,0)+IF(AND(X7<>"",'Official Results'!C14<>"",X7='Official Results'!C14),1,0)+IF(AND(Y7<>"",'Official Results'!C15<>"",'Official Results'!G15="Yes",Y7='Official Results'!C15),1,0) -> 3 | AB7: Netherlands | AC7: Japan | AD7: Sweden | AE7: =IF(AND(AB7<>"",'Official Results'!J13<>""),IF(AB7='Official Results'!J13,'Instructions & Rules'!$K$4,IF(AB7='Official Results'!J14,'Instructions & Rules'!$K$6,0)),0)+IF(AND(AC7<>"",'Official Results'!J14<>""),IF(AC7='Official Results'!J14,'Instructions & Rules'!$K$5,IF(AC7='Official Results'!J13,'Instructions & Rules'!$K$6,0)),0)+IF(AND(AD7<>"",'Official Results'!J15<>"",'Official Results'!N15="Yes"),IF(AD7='Official Results'!J15,'Instructions & Rules'!$K$7,0),0)+IF(AND(AB7='Official Results'!J13,AC7='Official Results'!J14,'Official Results'!J13<>"",'Official Results'!J14<>""),'Instructions & Rules'!$K$8,0)+IF(AND(AB7='Official Results'!J13,AC7='Official Results'!J14,AD7='Official Results'!J15,'Official Results'!N15="Yes"),'Instructions & Rules'!$K$9,0) -> 15 | AF7: =IF(AND(AB7<>"",'Official Results'!J13<>"",AB7='Official Results'!J13),1,0)+IF(AND(AC7<>"",'Official Results'!J14<>"",AC7='Official Results'!J14),1,0)+IF(AND(AD7<>"",'Official Results'!J15<>"",'Official Results'!N15="Yes",AD7='Official Results'!J15),1,0) -> 3 | AG7: Belgium | AH7: Egypt | AI7: IR Iran | AJ7: =IF(AND(AG7<>"",'Official Results'!Q13<>""),IF(AG7='Official Results'!Q13,'Instructions & Rules'!$K$4,IF(AG7='Official Results'!Q14,'Instructions & Rules'!$K$6,0)),0)+IF(AND(AH7<>"",'Official Results'!Q14<>""),IF(AH7='Official Results'!Q14,'Instructions & Rules'!$K$5,IF(AH7='Official Results'!Q13,'Instructions & Rules'!$K$6,0)),0)+IF(AND(AI7<>"",'Official Results'!Q15<>"",'Official Results'!U15="Yes"),IF(AI7='Official Results'!Q15,'Instructions & Rules'!$K$7,0),0)+IF(AND(AG7='Official Results'!Q13,AH7='Official Results'!Q14,'Official Results'!Q13<>"",'Official Results'!Q14<>""),'Instructions & Rules'!$K$8,0)+IF(AND(AG7='Official Results'!Q13,AH7='Official Results'!Q14,AI7='Official Results'!Q15,'Official Results'!U15="Yes"),'Instructions & Rules'!$K$9,0) -> 10 | AK7: =IF(AND(AG7<>"",'Official Results'!Q13<>"",AG7='Official Results'!Q13),1,0)+IF(AND(AH7<>"",'Official Results'!Q14<>"",AH7='Official Results'!Q14),1,0)+IF(AND(AI7<>"",'Official Results'!Q15<>"",'Official Results'!U15="Yes",AI7='Official Results'!Q15),1,0) -> 2 | AL7: Spain | AM7: Uruguay | AN7: Saudi Arabia | AO7: =IF(AND(AL7<>"",'Official Results'!X13<>""),IF(AL7='Official Results'!X13,'Instructions & Rules'!$K$4,IF(AL7='Official Results'!X14,'Instructions & Rules'!$K$6,0)),0)+IF(AND(AM7<>"",'Official Results'!X14<>""),IF(AM7='Official Results'!X14,'Instructions & Rules'!$K$5,IF(AM7='Official Results'!X13,'Instructions & Rules'!$K$6,0)),0)+IF(AND(AN7<>"",'Official Results'!X15<>"",'Official Results'!AB15="Yes"),IF(AN7='Official Results'!X15,'Instructions & Rules'!$K$7,0),0)+IF(AND(AL7='Official Results'!X13,AM7='Official Results'!X14,'Official Results'!X13<>"",'Official Results'!X14<>""),'Instructions & Rules'!$K$8,0)+IF(AND(AL7='Official Results'!X13,AM7='Official Results'!X14,AN7='Official Results'!X15,'Official Results'!AB15="Yes"),'Instructions & Rules'!$K$9,0) -> 4 | AP7: =IF(AND(AL7<>"",'Official Results'!X13<>"",AL7='Official Results'!X13),1,0)+IF(AND(AM7<>"",'Official Results'!X14<>"",AM7='Official Results'!X14),1,0)+IF(AND(AN7<>"",'Official Results'!X15<>"",'Official Results'!AB15="Yes",AN7='Official Results'!X15),1,0) -> 1 | AQ7: France | AR7: Norway | AS7: Iraq | AT7: =IF(AND(AQ7<>"",'Official Results'!C20<>""),IF(AQ7='Official Results'!C20,'Instructions & Rules'!$K$4,IF(AQ7='Official Results'!C21,'Instructions & Rules'!$K$6,0)),0)+IF(AND(AR7<>"",'Official Results'!C21<>""),IF(AR7='Official Results'!C21,'Instructions & Rules'!$K$5,IF(AR7='Official Results'!C20,'Instructions & Rules'!$K$6,0)),0)+IF(AND(AS7<>"",'Official Results'!C22<>"",'Official Results'!G22="Yes"),IF(AS7='Official Results'!C22,'Instructions & Rules'!$K$7,0),0)+IF(AND(AQ7='Official Results'!C20,AR7='Official Results'!C21,'Official Results'!C20<>"",'Official Results'!C21<>""),'Instructions & Rules'!$K$8,0)+IF(AND(AQ7='Official Results'!C20,AR7='Official Results'!C21,AS7='Official Results'!C22,'Official Results'!G22="Yes"),'Instructions & Rules'!$K$9,0) -> 10 | AU7: =IF(AND(AQ7<>"",'Official Results'!C20<>"",AQ7='Official Results'!C20),1,0)+IF(AND(AR7<>"",'Official Results'!C21<>"",AR7='Official Results'!C21),1,0)+IF(AND(AS7<>"",'Official Results'!C22<>"",'Official Results'!G22="Yes",AS7='Official Results'!C22),1,0) -> 2 | AV7: Argentina | AW7: Austria | AX7: Algeria | AY7: =IF(AND(AV7<>"",'Official Results'!J20<>""),IF(AV7='Official Results'!J20,'Instructions & Rules'!$K$4,IF(AV7='Official Results'!J21,'Instructions & Rules'!$K$6,0)),0)+IF(AND(AW7<>"",'Official Results'!J21<>""),IF(AW7='Official Results'!J21,'Instructions & Rules'!$K$5,IF(AW7='Official Results'!J20,'Instructions & Rules'!$K$6,0)),0)+IF(AND(AX7<>"",'Official Results'!J22<>"",'Official Results'!N22="Yes"),IF(AX7='Official Results'!J22,'Instructions & Rules'!$K$7,0),0)+IF(AND(AV7='Official Results'!J20,AW7='Official Results'!J21,'Official Results'!J20<>"",'Official Results'!J21<>""),'Instructions & Rules'!$K$8,0)+IF(AND(AV7='Official Results'!J20,AW7='Official Results'!J21,AX7='Official Results'!J22,'Official Results'!N22="Yes"),'Instructions & Rules'!$K$9,0) -> 15 | AZ7: =IF(AND(AV7<>"",'Official Results'!J20<>"",AV7='Official Results'!J20),1,0)+IF(AND(AW7<>"",'Official Results'!J21<>"",AW7='Official Results'!J21),1,0)+IF(AND(AX7<>"",'Official Results'!J22<>"",'Official Results'!N22="Yes",AX7='Official Results'!J22),1,0) -> 3 | BA7: Portugal | BB7: Colombia | BC7: Uzbekistan | BD7: =IF(AND(BA7<>"",'Official Results'!Q20<>""),IF(BA7='Official Results'!Q20,'Instructions & Rules'!$K$4,IF(BA7='Official Results'!Q21,'Instructions & Rules'!$K$6,0)),0)+IF(AND(BB7<>"",'Official Results'!Q21<>""),IF(BB7='Official Results'!Q21,'Instructions & Rules'!$K$5,IF(BB7='Official Results'!Q20,'Instructions & Rules'!$K$6,0)),0)+IF(AND(BC7<>"",'Official Results'!Q22<>"",'Official Results'!U22="Yes"),IF(BC7='Official Results'!Q22,'Instructions & Rules'!$K$7,0),0)+IF(AND(BA7='Official Results'!Q20,BB7='Official Results'!Q21,'Official Results'!Q20<>"",'Official Results'!Q21<>""),'Instructions & Rules'!$K$8,0)+IF(AND(BA7='Official Results'!Q20,BB7='Official Results'!Q21,BC7='Official Results'!Q22,'Official Results'!U22="Yes"),'Instructions & Rules'!$K$9,0) -> 2 | BE7: =IF(AND(BA7<>"",'Official Results'!Q20<>"",BA7='Official Results'!Q20),1,0)+IF(AND(BB7<>"",'Official Results'!Q21<>"",BB7='Official Results'!Q21),1,0)+IF(AND(BC7<>"",'Official Results'!Q22<>"",'Official Results'!U22="Yes",BC7='Official Results'!Q22),1,0) -> 0 | BF7: England | BG7: Ghana | BH7: Croatia | BI7: =IF(AND(BF7<>"",'Official Results'!X20<>""),IF(BF7='Official Results'!X20,'Instructions & Rules'!$K$4,IF(BF7='Official Results'!X21,'Instructions & Rules'!$K$6,0)),0)+IF(AND(BG7<>"",'Official Results'!X21<>""),IF(BG7='Official Results'!X21,'Instructions & Rules'!$K$5,IF(BG7='Official Results'!X20,'Instructions & Rules'!$K$6,0)),0)+IF(AND(BH7<>"",'Official Results'!X22<>"",'Official Results'!AB22="Yes"),IF(BH7='Official Results'!X22,'Instructions & Rules'!$K$7,0),0)+IF(AND(BF7='Official Results'!X20,BG7='Official Results'!X21,'Official Results'!X20<>"",'Official Results'!X21<>""),'Instructions & Rules'!$K$8,0)+IF(AND(BF7='Official Results'!X20,BG7='Official Results'!X21,BH7='Official Results'!X22,'Official Results'!AB22="Yes"),'Instructions & Rules'!$K$9,0) -> 4 | BJ7: =IF(AND(BF7<>"",'Official Results'!X20<>"",BF7='Official Results'!X20),1,0)+IF(AND(BG7<>"",'Official Results'!X21<>"",BG7='Official Results'!X21),1,0)+IF(AND(BH7<>"",'Official Results'!X22<>"",'Official Results'!AB22="Yes",BH7='Official Results'!X22),1,0) -> 1 | BK7: =SUM(F7,K7,P7,U7,Z7,AE7,AJ7,AO7,AT7,AY7,BD7,BI7) -> 94 | BL7: =SUM(G7,L7,Q7,V7,AA7,AF7,AK7,AP7,AU7,AZ7,BE7,BJ7) -> 19 | BM7: =SUM(COUNTIF(C7:E7,"<>"),COUNTIF(H7:J7,"<>"),COUNTIF(M7:O7,"<>"),COUNTIF(R7:T7,"<>"),COUNTIF(W7:Y7,"<>"),COUNTIF(AB7:AD7,"<>"),COUNTIF(AG7:AI7,"<>"),COUNTIF(AL7:AN7,"<>"),COUNTIF(AQ7:AS7,"<>"),COUNTIF(AV7:AX7,"<>"),COUNTIF(BA7:BC7,"<>"),COUNTIF(BF7:BH7,"<>"))/36 -> 1
